<mujoco model="panda_wrist">
    <actuator>
	<!-- Physical limits of the actuator. -->
        <motor ctrllimited="true" ctrlrange="-80.0 80.0" joint="joint1" name="torq_j1"/>
        <motor ctrllimited="true" ctrlrange="-80.0 80.0" joint="joint2" name="torq_j2"/>
        <motor ctrllimited="true" ctrlrange="-80.0 80.0" joint="joint3" name="torq_j3"/>
        <motor ctrllimited="true" ctrlrange="-80.0 80.0" joint="joint4" name="torq_j4"/>
        <motor ctrllimited="true" ctrlrange="-80.0 80.0" joint="joint5" name="torq_j5"/>
        <motor ctrllimited="true" ctrlrange="-12.0 12.0" joint="joint6" name="torq_j6"/>
        <motor ctrllimited="true" ctrlrange="-12.0 12.0" joint="joint7" name="torq_j7"/>
		<!-- <position ctrllimited="true" ctrlrange="-3.14 3.14" joint="wristPitchJoint" kp="1000" name="wristPitchJoint" forcelimited="true" forcerange="-20 20"/>
        <position ctrllimited="true" ctrlrange="-3.14 3.14" joint="wristYawJoint" kp="1000" name="wristYawJoint" forcelimited="true" forcerange="-20 20"/> -->
        <motor ctrllimited="true" ctrlrange="-10.0 10.0" joint="wristPitchJoint" name="torq_jwristPitchJoint"/>
        <motor ctrllimited="true" ctrlrange="-10.0 10.0" joint="wristRollJoint" name="torq_wristRollJoint"/>
    </actuator>

    <asset>
        <mesh name="link0" file="meshes/link0.stl" />
        <mesh name="link1" file="meshes/link1.stl" />
        <mesh name="link2" file="meshes/link2.stl" />
        <mesh name="link3" file="meshes/link3.stl" />
        <mesh name="link4" file="meshes/link4.stl" />
        <mesh name="link5" file="meshes/link5.stl" />
        <mesh name="link6" file="meshes/link6.stl" />
        <mesh name="link7" file="meshes/link7.stl" />
        <mesh name="link0_vis" file="meshes/link0_vis.stl" />
        <mesh name="link1_vis" file="meshes/link1_vis.stl" />
        <mesh name="link2_vis" file="meshes/link2_vis.stl" />
        <mesh name="link3_vis" file="meshes/link3_vis.stl" />
        <mesh name="link4_vis" file="meshes/link4_vis.stl" />
        <mesh name="link5_vis" file="meshes/link5_vis.stl" />
        <mesh name="link6_vis" file="meshes/link6_vis.stl" />
        <mesh name="link7_vis" file="meshes/link7_vis.stl" />

		<mesh name="forearm0_col" file="meshes/geared_wrist_convex_piece_0.stl" />
		<mesh name="forearm1_col" file="meshes/geared_wrist_convex_piece_1.stl" />
		<mesh name="forearm2_col" file="meshes/geared_wrist_convex_piece_2.stl" />
		<mesh name="box_col" file="meshes/attachment.stl" />
		<mesh name="palm_mount_col" file="meshes/attachmenthub.stl" />

    </asset>											

    <worldbody>
	        <body name="base" pos="0 0 0">
            <!-- robot view -->
            <!--<camera mode="fixed" name="robotview" pos="1.0 0 0.4" quat="0.653 0.271 0.271 0.653"/>-->
            <inertial diaginertia="0 0 0" mass="0" pos="0 0 0"/>
            <!-- mount attached here -->
            <body name="link0" pos="0 0 0">
                <inertial pos="0 0 0.05" mass="4" diaginertia="0.4 0.4 0.4" />
                <geom type="mesh" contype="0" conaffinity="0" group="1" mesh="link0_vis" name="link0_visual" rgba="1 1 1 .3"  />
                <geom type="mesh" group="0" mesh="link0" name="link0_collision"/>
                <body name="link1" pos="0 0 0.333">
                    <inertial pos="0 0 -0.07" mass="3" diaginertia="0.3 0.3 0.3" />
                    <joint name="joint1" pos="0 0 0" axis="0 0 1" limited="true" range="-2.8973 2.8973" damping="0.1"/>
                    <geom type="mesh" contype="0" conaffinity="0" group="1" mesh="link1_vis" name="link1_visual" rgba="1 1 1 .3"  />
                    <geom type="mesh" group="0" mesh="link1" name="link1_collision"/>
                    <body name="link2" pos="0 0 0" quat="0.707107 -0.707107 0 0">
                        <inertial pos="0 -0.1 0" mass="3" diaginertia="0.3 0.3 0.3" />
                        <joint name="joint2" pos="0 0 0" axis="0 0 1" limited="true" range="-1.7628 1.7628" damping="0.1"/>
                        <geom type="mesh" contype="0" conaffinity="0" group="1" mesh="link2_vis" name="link2_visual" rgba="1 1 1 .3"  />
                        <geom type="mesh" group="0" mesh="link2" name="link2_collision"/>
                        <body name="link3" pos="0 -0.316 0" quat="0.707107 0.707107 0 0">
                            <inertial pos="0.04 0 -0.05" mass="2" diaginertia="0.2 0.2 0.2" />
                            <joint name="joint3" pos="0 0 0" axis="0 0 1" limited="true" range="-2.8973 2.8973" damping="0.1"/>
                            <geom type="mesh" contype="0" conaffinity="0" group="1" mesh="link3_vis" name="link3_visual" rgba="1 1 1 .3"  />
                            <geom type="mesh" group="0" mesh="link3" name="link3_collision"/>
                            <body name="link4" pos="0.0825 0 0" quat="0.707107 0.707107 0 0">
                                <inertial pos="-0.04 0.05 0" mass="2" diaginertia="0.2 0.2 0.2" />
                                <joint name="joint4" pos="0 0 0" axis="0 0 1" limited="true" range="-3.0718 -0.0698" damping="0.1"/>
                                <geom type="mesh" contype="0" conaffinity="0" group="1" mesh="link4_vis" name="link4_visual" rgba="1 1 1 .3"  />
                                <geom type="mesh" group="0" mesh="link4" name="link4_collision"/>
                                <body name="link5" pos="-0.0825 0.384 0" quat="0.707107 -0.707107 0 0">
                                    <inertial pos="0 0 -0.15" mass="2" diaginertia="0.2 0.2 0.2" />
                                    <joint name="joint5" pos="0 0 0" axis="0 0 1" limited="true" range="-2.8973 2.8973" damping="0.1"/>
                                    <geom type="mesh" contype="0" conaffinity="0" group="1" mesh="link5_vis" name="link5_visual" rgba="1 1 1 .3"  />
                                    <geom type="mesh" group="0" mesh="link5" name="link5_collision"/>
                                    <body name="link6" pos="0 0 0" quat="0.707107 0.707107 0 0">
                                        <inertial pos="0.06 0 0" mass="1.5" diaginertia="0.1 0.1 0.1" />
                                        <joint name="joint6" pos="0 0 0" axis="0 0 1" limited="true" range="-0.0175 3.7525" damping="0.01"/>
                                        <geom type="mesh" contype="0" conaffinity="0" group="1" mesh="link6_vis" name="link6_visual" rgba="1 1 1 .3"  />
                                        <geom type="mesh" group="0" mesh="link6" name="link6_collision"/>
                                        <body name="link7" pos="0.088 0 0" quat="0.707107 0.707107 0 0">
                                            <inertial pos="0 0 0.08" mass="0.5" diaginertia="0.05 0.05 0.05" />
                                            <joint name="joint7" pos="0 0 0" axis="0 0 1" limited="true" range="-2.8973 2.8973" damping="0.01"/>
                                            <geom type="mesh" contype="0" conaffinity="0" group="1" mesh="link7_vis" name="link7_visual" rgba="1 1 1 .3"  />
                                            <!-- <geom type="mesh" group="0" mesh="link7" name="link7_collision"/> -->
											
														
											<!-- <body name="forearm_right_old" pos="0 0 0.1065" quat="-0.27059805  0.65328148  0.27059805  0.65328148"> -->
                                            <body name="forearm" pos="0 0 0.11" quat="0 0.924 0.383 0">
												<inertial pos="1.04812e-09 7.62841e-09 -0.0475109" quat="0.707107 9.65677e-07 -9.65677e-07 0.707107" mass="0.300968" diaginertia="0.000414174 0.000357351 0.000144099" />
												<geom mesh="forearm0_col" type="mesh" contype="0" conaffinity="0" group="1" pos="0 0 -0.069" />
												<geom mesh="forearm1_col" type="mesh" contype="0" conaffinity="0" group="1" pos="0 0 -0.069" />
												<geom mesh="forearm2_col" type="mesh" contype="0" conaffinity="0" group="1" pos="0 0 -0.069" />
												<!-- <geom type="mesh" group="0" mesh="forearm0_col" name="forearm0_collision" pos="0 0 -0.069" />
												<geom type="mesh" group="0" mesh="forearm1_col" name="forearm1_collision" pos="0 0 -0.069" />
												<geom type="mesh" group="0" mesh="forearm2_col" name="forearm2_collision" pos="0 0 -0.069" /> -->
												
												<body name="box" pos="0.00791653 0 -0.101" quat="0.5 0.5 0.5 0.5">
                									<inertial pos="0 0 -0.00791653" quat="0.5 0.5 -0.5 0.5" mass="0.00673962" diaginertia="3.52611e-07 3.17099e-07 3.17099e-07" />
													<joint name="wristPitchJoint" pos="0 0 0" axis="0 0 1" limited="true" damping="0.5"  range="-1.74533 1.74533"/>
													<geom mesh="box_col" type="mesh" contype="0" conaffinity="0" group="1" pos="0 0.032 -0.00791653" quat="0.5 -0.5 -0.5 -0.5" />				
													<!-- <geom type="mesh" group="0" mesh="box_col" name="box_collision" pos="0 0.032 -0.00791653" quat="0.5 -0.5 -0.5 -0.5"/> -->
													
													<body name="palm_mount" pos="0 -0.00885881 -0.00791653" quat="0.5 -0.5 -0.5 -0.5">
                    									<inertial pos="0 0 -0.00859844" quat="0.5 0.5 -0.5 0.5" mass="0.00862353" diaginertia="5.54493e-07 4.46044e-07 4.46044e-07" />
														<joint name="wristRollJoint" pos="0 0 0" axis="0 0 1" />
														<geom mesh="palm_mount_col" type="mesh" contype="0" conaffinity="0" group="1" pos="0 0 0.0408588" />
														<!-- <geom type="mesh" group="0" mesh="palm_mount_col" name="palm_mount_collision" pos="0 0 0.0408588" /> -->

															<!-- rotate 135deg to align physically to the tool-->
															<body name="right_hand" pos="0 0 0" quat="1 0 0 0">
																<inertial pos="0 0 0" mass="0.5" diaginertia="0.05 0.05 0.05" />
																<!-- This camera points out from the eef. -->
																<camera mode="fixed" name="eye_in_hand" pos="0.05 0 0" quat="0 0.707108 0.707108 0" fovy="75"/>
																<!-- to add gripper -->
														</body>
													</body>
												</body>
                                            </body>
                                        </body>
                                    </body>
                                </body>
                            </body>
                        </body>
                    </body>
                </body>
            </body>
        </body>
    </worldbody>
</mujoco>
